Workbook

Sheet Aggregate Forecast
B1: TSA Overall
B2: Description | C2: ='Virtual Schools'!C2 -> SY 2026 | D2: ='Virtual Schools'!D2 -> SY 2027 | E2: ='Virtual Schools'!E2 -> SY 2028 | F2: ='Virtual Schools'!F2 -> SY 2029 | G2: ='Virtual Schools'!G2 -> SY 2030 | H2: ='Virtual Schools'!H2 -> SY 2031 | I2: ='Virtual Schools'!I2 -> SY 2032 | J2: ='Virtual Schools'!J2 -> SY 2033 | ... M2: ='Virtual Schools'!M2 -> SY 2036
B3: Tuition Revenue
B4: Virtual Schools | C4: ='Virtual Schools'!C7 -> 104740000 | D4: ='Virtual Schools'!D7 -> 209480000 | E4: ='Virtual Schools'!E7 -> 314220000 | F4: ='Virtual Schools'!F7 -> 418960000 | G4: ='Virtual Schools'!G7 -> 523700000 | H4: ='Virtual Schools'!H7 -> 628440000 | I4: ='Virtual Schools'!I7 -> 733180000 | J4: ='Virtual Schools'!J7 -> 837920000 | ... M4: ='Virtual Schools'!M7 -> 1047400000
B5: # Students | C5: ='Virtual Schools'!C14 -> 10000 | D5: ='Virtual Schools'!D14 -> 20000 | E5: ='Virtual Schools'!E14 -> 30000 | F5: ='Virtual Schools'!F14 -> 40000 | G5: ='Virtual Schools'!G14 -> 50000 | H5: ='Virtual Schools'!H14 -> 60000 | I5: ='Virtual Schools'!I14 -> 70000 | J5: ='Virtual Schools'!J14 -> 80000 | ... M5: ='Virtual Schools'!M14 -> 100000
B7: Microschools | C7: =Microschools!C33 -> 5925000 | D7: =Microschools!D33 -> 18000000 | E7: =Microschools!E33 -> 54000000 | F7: =Microschools!F33 -> 162000000 | G7: =Microschools!G33 -> 486000000 | H7: =Microschools!H33 -> 1232250000 | I7: =Microschools!I33 -> 1500000000 | J7: =Microschools!J33 -> 1500000000 | ... M7: =Microschools!M33 -> 1500000000
B8: # Students | C8: =Microschools!C31 -> 395 | D8: =Microschools!D31 -> 1200 | E8: =Microschools!E31 -> 3600 | F8: =Microschools!F31 -> 10800 | G8: =Microschools!G31 -> 32400 | H8: =Microschools!H31 -> 82150 | I8: =Microschools!I31 -> 100000 | J8: =Microschools!J31 -> 100000 | ... M8: =Microschools!M31 -> 100000
B10: Mid-Sized Schools | C10: ='Mid-Sized Schools'!C33 -> 1000000 | D10: ='Mid-Sized Schools'!D33 -> 11550000 | E10: ='Mid-Sized Schools'!E33 -> 69650000 | F10: ='Mid-Sized Schools'!F33 -> 186550000 | G10: ='Mid-Sized Schools'!G33 -> 465500000 | H10: ='Mid-Sized Schools'!H33 -> 990500000 | I10: ='Mid-Sized Schools'!I33 -> 1750000000 | J10: ='Mid-Sized Schools'!J33 -> 2625000000 | ... M10: ='Mid-Sized Schools'!M33 -> 7433125000
B11: # Students | C11: ='Mid-Sized Schools'!C31 -> 40 | D11: ='Mid-Sized Schools'!D31 -> 462 | E11: ='Mid-Sized Schools'!E31 -> 2786 | F11: ='Mid-Sized Schools'!F31 -> 7462 | G11: ='Mid-Sized Schools'!G31 -> 18620 | H11: ='Mid-Sized Schools'!H31 -> 39620 | I11: ='Mid-Sized Schools'!I31 -> 70000 | J11: ='Mid-Sized Schools'!J31 -> 105000 | ... M11: ='Mid-Sized Schools'!M31 -> 297325
B13: Flagships | C13: ='Flagship Schools'!C34 -> 0 | D13: ='Flagship Schools'!D34 -> 0 | E13: ='Flagship Schools'!E34 -> 0 | F13: ='Flagship Schools'!F34 -> 0 | G13: ='Flagship Schools'!G34 -> 0 | H13: ='Flagship Schools'!H34 -> 24750000 | I13: ='Flagship Schools'!I34 -> 50250000 | J13: ='Flagship Schools'!J34 -> 99750000 | ... M13: ='Flagship Schools'!M34 -> 200250000
B14: # Students | C14: ='Flagship Schools'!C32 -> 0 | D14: ='Flagship Schools'!D32 -> 0 | E14: ='Flagship Schools'!E32 -> 0 | F14: ='Flagship Schools'!F32 -> 0 | G14: ='Flagship Schools'!G32 -> 0 | H14: ='Flagship Schools'!H32 -> 495 | I14: ='Flagship Schools'!I32 -> 1005 | J14: ='Flagship Schools'!J32 -> 1995 | ... M14: ='Flagship Schools'!M32 -> 4005
B16: Total Revenue | C16: =C4+C7+C10+C13 -> 111665000 | D16: =D4+D7+D10+D13 -> 239030000 | E16: =E4+E7+E10+E13 -> 437870000 | F16: =F4+F7+F10+F13 -> 767510000 | G16: =G4+G7+G10+G13 -> 1475200000 | H16: =H4+H7+H10+H13 -> 2875940000 | I16: =I4+I7+I10+I13 -> 4033430000 | J16: =J4+J7+J10+J13 -> 5062670000 | ... M16: =M4+M7+M10+M13 -> 10180775000
B17: Total # of Students | C17: =C5+C8+C11+C14 -> 10435 | D17: =D5+D8+D11+D14 -> 21662 | E17: =E5+E8+E11+E14 -> 36386 | F17: =F5+F8+F11+F14 -> 58262 | G17: =G5+G8+G11+G14 -> 101020 | H17: =H5+H8+H11+H14 -> 182265 | I17: =I5+I8+I11+I14 -> 241005 | J17: =J5+J8+J11+J14 -> 286995 | ... M17: =M5+M8+M11+M14 -> 501330
B19: Timeback | C19: =('Virtual Schools'!C21*'Virtual Schools'!C14)+(Microschools!C31*Microschools!C15)+('Mid-Sized Schools'!C13*'Mid-Sized Schools'!C31)+('Flagship Schools'!C13*'Flagship Schools'!C32) -> 21385000 | D19: =('Virtual Schools'!D21*'Virtual Schools'!D14)+(Microschools!D31*Microschools!D15)+('Mid-Sized Schools'!D13*'Mid-Sized Schools'!D31)+('Flagship Schools'!D13*'Flagship Schools'!D32) -> 45910000 | E19: =('Virtual Schools'!E21*'Virtual Schools'!E14)+(Microschools!E31*Microschools!E15)+('Mid-Sized Schools'!E13*'Mid-Sized Schools'!E31)+('Flagship Schools'!E13*'Flagship Schools'!E32) -> 84730000 | F19: =('Virtual Schools'!F21*'Virtual Schools'!F14)+(Microschools!F31*Microschools!F15)+('Mid-Sized Schools'!F13*'Mid-Sized Schools'!F31)+('Flagship Schools'!F13*'Flagship Schools'!F32) -> 149710000 | G19: =('Virtual Schools'!G21*'Virtual Schools'!G14)+(Microschools!G31*Microschools!G15)+('Mid-Sized Schools'!G13*'Mid-Sized Schools'!G31)+('Flagship Schools'!G13*'Flagship Schools'!G32) -> 290300000 | H19: =('Virtual Schools'!H21*'Virtual Schools'!H14)+(Microschools!H31*Microschools!H15)+('Mid-Sized Schools'!H13*'Mid-Sized Schools'!H31)+('Flagship Schools'!H13*'Flagship Schools'!H32) -> 569500000 | I19: =('Virtual Schools'!I21*'Virtual Schools'!I14)+(Microschools!I31*Microschools!I15)+('Mid-Sized Schools'!I13*'Mid-Sized Schools'!I31)+('Flagship Schools'!I13*'Flagship Schools'!I32) -> 800050000 | J19: =('Virtual Schools'!J21*'Virtual Schools'!J14)+(Microschools!J31*Microschools!J15)+('Mid-Sized Schools'!J13*'Mid-Sized Schools'!J31)+('Flagship Schools'!J13*'Flagship Schools'!J32) -> 1004950000 | ... M19: =('Virtual Schools'!M21*'Virtual Schools'!M14)+(Microschools!M31*Microschools!M15)+('Mid-Sized Schools'!M13*'Mid-Sized Schools'!M31)+('Flagship Schools'!M13*'Flagship Schools'!M32) -> 2026675000
B21: EBITDA (ex-Marketing)
B22: Virtual Schools | C22: ='Virtual Schools'!C7-'Virtual Schools'!C23 -> 37240000 | D22: ='Virtual Schools'!D7-'Virtual Schools'!D23 -> 74480000 | E22: ='Virtual Schools'!E7-'Virtual Schools'!E23 -> 111720000 | F22: ='Virtual Schools'!F7-'Virtual Schools'!F23 -> 148960000 | G22: ='Virtual Schools'!G7-'Virtual Schools'!G23 -> 186200000 | H22: ='Virtual Schools'!H7-'Virtual Schools'!H23 -> 223440000 | I22: ='Virtual Schools'!I7-'Virtual Schools'!I23 -> 260680000 | J22: ='Virtual Schools'!J7-'Virtual Schools'!J23 -> 297920000 | ... M22: ='Virtual Schools'!M7-'Virtual Schools'!M23 -> 372400000
B23: Microschools | C23: =Microschools!C35 -> 1382500 | D23: =Microschools!D35 -> 4200000 | E23: =Microschools!E35 -> 12600000 | F23: =Microschools!F35 -> 37800000 | G23: =Microschools!G35 -> 113400000 | H23: =Microschools!H35 -> 287525000 | I23: =Microschools!I35 -> 350000000 | J23: =Microschools!J35 -> 350000000 | ... M23: =Microschools!M35 -> 350000000
B24: Mid-Sized Schools | C24: ='Mid-Sized Schools'!C67 -> -1621036 | D24: ='Mid-Sized Schools'!D67 -> -5415095 | E24: ='Mid-Sized Schools'!E67 -> 8287895 | F24: ='Mid-Sized Schools'!F67 -> 25822685 | G24: ='Mid-Sized Schools'!G67 -> 89594050 | H24: ='Mid-Sized Schools'!H67 -> 254418150 | I24: ='Mid-Sized Schools'!I67 -> 515551400 | J24: ='Mid-Sized Schools'!J67 -> 824120500 | ... M24: ='Mid-Sized Schools'!M67 -> 2240090038
B25: Flagships | C25: ='Flagship Schools'!C67 -> 0 | D25: ='Flagship Schools'!D67 -> 0 | E25: ='Flagship Schools'!E67 -> 0 | F25: ='Flagship Schools'!F67 -> -1600000 | G25: ='Flagship Schools'!G67 -> -1600000 | H25: ='Flagship Schools'!H67 -> 14257412 | I25: ='Flagship Schools'!I67 -> 32243838 | J25: ='Flagship Schools'!J67 -> 65558662 | ... M25: ='Flagship Schools'!M67 -> 1.3484634e+08
B26: Total EBITDA (ex-Marketing) | C26: =SUM(C22:C25) -> 37001464 | D26: =SUM(D22:D25) -> 73264905 | E26: =SUM(E22:E25) -> 132607895 | F26: =SUM(F22:F25) -> 210982685 | G26: =SUM(G22:G25) -> 387594050 | H26: =SUM(H22:H25) -> 7.7964056e+08 | I26: =SUM(I22:I25) -> 1158475238 | J26: =SUM(J22:J25) -> 1537599163 | ... M26: =SUM(M22:M25) -> 3097336375
B27: Margin | C27: =C26/C16 -> 0.33136134 | D27: =D26/D16 -> 0.30650925 | E27: =E26/E16 -> 0.30284764 | F27: =F26/F16 -> 0.27489242 | G27: =G26/G16 -> 0.26274 | H27: =H26/H16 -> 0.27109069 | I27: =I26/I16 -> 0.28721838 | J27: =J26/J16 -> 0.30371309 | ... M27: =M26/M16 -> 0.30423385
B29: Marketing
B30: Top-of-funnel | C30: ='Virtual Schools'!C26+Microschools!C38+'Mid-Sized Schools'!C71+'Flagship Schools'!C71 -> 5131000 | D30: ='Virtual Schools'!D26+Microschools!D38+'Mid-Sized Schools'!D71+'Flagship Schools'!D71 -> 8305500 | E30: ='Virtual Schools'!E26+Microschools!E38+'Mid-Sized Schools'!E71+'Flagship Schools'!E71 -> 13697000 | F30: ='Virtual Schools'!F26+Microschools!F38+'Mid-Sized Schools'!F71+'Flagship Schools'!F71 -> 22084000 | G30: ='Virtual Schools'!G26+Microschools!G38+'Mid-Sized Schools'!G71+'Flagship Schools'!G71 -> 41241000 | H30: ='Virtual Schools'!H26+Microschools!H38+'Mid-Sized Schools'!H71+'Flagship Schools'!H71 -> 76475000 | I30: ='Virtual Schools'!I26+Microschools!I38+'Mid-Sized Schools'!I71+'Flagship Schools'!I71 -> 90464654 | J30: ='Virtual Schools'!J26+Microschools!J38+'Mid-Sized Schools'!J71+'Flagship Schools'!J71 -> 1.0240062e+08 | ... M30: ='Virtual Schools'!M26+Microschools!M38+'Mid-Sized Schools'!M71+'Flagship Schools'!M71 -> 2.0691469e+08
B31: Bottom-of-funnel | C31: ='Virtual Schools'!C27+Microschools!C39+'Mid-Sized Schools'!C72+'Flagship Schools'!C72 -> 20652000 | D31: ='Virtual Schools'!D27+Microschools!D39+'Mid-Sized Schools'!D72+'Flagship Schools'!D72 -> 33718500 | E31: ='Virtual Schools'!E27+Microschools!E39+'Mid-Sized Schools'!E72+'Flagship Schools'!E72 -> 56273000 | F31: ='Virtual Schools'!F27+Microschools!F39+'Mid-Sized Schools'!F72+'Flagship Schools'!F72 -> 92791000 | G31: ='Virtual Schools'!G27+Microschools!G39+'Mid-Sized Schools'!G72+'Flagship Schools'!G72 -> 178329000 | H31: ='Virtual Schools'!H27+Microschools!H39+'Mid-Sized Schools'!H72+'Flagship Schools'!H72 -> 338470000 | I31: ='Virtual Schools'!I27+Microschools!I39+'Mid-Sized Schools'!I72+'Flagship Schools'!I72 -> 3.9029412e+08 | J31: ='Virtual Schools'!J27+Microschools!J39+'Mid-Sized Schools'!J72+'Flagship Schools'!J72 -> 4.3335246e+08 | ... M31: ='Virtual Schools'!M27+Microschools!M39+'Mid-Sized Schools'!M72+'Flagship Schools'!M72 -> 8.5140877e+08
B32: Total Marketing | C32: =C30+C31 -> 25783000 | D32: =D30+D31 -> 42024000 | E32: =E30+E31 -> 69970000 | F32: =F30+F31 -> 114875000 | G32: =G30+G31 -> 219570000 | H32: =H30+H31 -> 414945000 | I32: =I30+I31 -> 4.8075877e+08 | J32: =J30+J31 -> 5.3575308e+08 | ... M32: =M30+M31 -> 1058323462
B34: EBITDA
B35: Virtual Schools | C35: ='Virtual Schools'!C30 -> 37240000 | D35: ='Virtual Schools'!D30 -> 74480000 | E35: ='Virtual Schools'!E30 -> 111720000 | F35: ='Virtual Schools'!F30 -> 148960000 | G35: ='Virtual Schools'!G30 -> 186200000 | H35: ='Virtual Schools'!H30 -> 223440000 | I35: ='Virtual Schools'!I30 -> 260680000 | J35: ='Virtual Schools'!J30 -> 297920000 | ... M35: ='Virtual Schools'!M30 -> 372400000
B36: Microschools | C36: =Microschools!C44 -> 614500 | D36: =Microschools!D44 -> 1221000 | E36: =Microschools!E44 -> 3690000 | F36: =Microschools!F44 -> 11070000 | G36: =Microschools!G44 -> 33210000 | H36: =Microschools!H44 -> 92105000 | I36: =Microschools!I44 -> 179387000 | J36: =Microschools!J44 -> 207500000 | ... M36: =Microschools!M44 -> 207500000
B37: Mid-Sized Schools | C37: ='Mid-Sized Schools'!C75 -> -1636036 | D37: ='Mid-Sized Schools'!D75 -> -7585095 | E37: ='Mid-Sized Schools'!E75 -> -4022105 | F37: ='Mid-Sized Schools'!F75 -> -1697315 | G37: ='Mid-Sized Schools'!G75 -> 22714050 | H37: ='Mid-Sized Schools'!H75 -> 121743150 | I37: ='Mid-Sized Schools'!I75 -> 304771400 | J37: ='Mid-Sized Schools'!J75 -> 545090500 | ... M37: ='Mid-Sized Schools'!M75 -> 1449565038
B38: Flagships | C38: ='Flagship Schools'!C75 -> 0 | D38: ='Flagship Schools'!D75 -> 0 | E38: ='Flagship Schools'!E75 -> 0 | F38: ='Flagship Schools'!F75 -> -1600000 | G38: ='Flagship Schools'!G75 -> -1600000 | H38: ='Flagship Schools'!H75 -> 11782412 | I38: ='Flagship Schools'!I75 -> 29128068 | J38: ='Flagship Schools'!J75 -> 59460586 | ... M38: ='Flagship Schools'!M75 -> 128297876
B39: Total EBITDA | C39: =SUM(C35:C38) -> 36218464 | D39: =SUM(D35:D38) -> 68115905 | E39: =SUM(E35:E38) -> 111387895 | F39: =SUM(F35:F38) -> 156732685 | G39: =SUM(G35:G38) -> 240524050 | H39: =SUM(H35:H38) -> 4.4907056e+08 | I39: =SUM(I35:I38) -> 7.7396647e+08 | J39: =SUM(J35:J38) -> 1109971086 | ... M39: =SUM(M35:M38) -> 2157762913
B40: Margin | C40: =C39/C16 -> 0.32434929 | D40: =D39/D16 -> 0.28496802 | E40: =E39/E16 -> 0.25438577 | F40: =F39/F16 -> 0.20420931 | G40: =G39/G16 -> 0.16304504 | H40: =H39/H16 -> 0.1561474 | I40: =I39/I16 -> 0.19188791 | J40: =J39/J16 -> 0.21924619 | ... M40: =M39/M16 -> 0.21194486
B42: Pre-Tax Cash Flows
B43: Virtual Schools | C43: ='Virtual Schools'!C32 -> 37240000 | D43: ='Virtual Schools'!D32 -> 74480000 | E43: ='Virtual Schools'!E32 -> 111720000 | F43: ='Virtual Schools'!F32 -> 148960000 | G43: ='Virtual Schools'!G32 -> 186200000 | H43: ='Virtual Schools'!H32 -> 223440000 | I43: ='Virtual Schools'!I32 -> 260680000 | J43: ='Virtual Schools'!J32 -> 297920000 | ... M43: ='Virtual Schools'!M32 -> 372400000
B44: Microschools | C44: =Microschools!C44 -> 614500 | D44: =Microschools!D44 -> 1221000 | E44: =Microschools!E44 -> 3690000 | F44: =Microschools!F44 -> 11070000 | G44: =Microschools!G44 -> 33210000 | H44: =Microschools!H44 -> 92105000 | I44: =Microschools!I44 -> 179387000 | J44: =Microschools!J44 -> 207500000 | ... M44: =Microschools!M44 -> 207500000
B45: Mid-Sized Schools | C45: ='Mid-Sized Schools'!C75-'Mid-Sized Schools'!C54 -> -26636036 | D45: ='Mid-Sized Schools'!D75-'Mid-Sized Schools'!D54 -> -267585095 | E45: ='Mid-Sized Schools'!E75-'Mid-Sized Schools'!E54 -> -329022105 | F45: ='Mid-Sized Schools'!F75-'Mid-Sized Schools'!F54 -> -976697315 | G45: ='Mid-Sized Schools'!G75-'Mid-Sized Schools'!G54 -> -1602285950 | H45: ='Mid-Sized Schools'!H75-'Mid-Sized Schools'!H54 -> -1503256850 | I45: ='Mid-Sized Schools'!I75-'Mid-Sized Schools'!I54 -> -1320228600 | J45: ='Mid-Sized Schools'!J75-'Mid-Sized Schools'!J54 -> -1079909500 | ... M45: ='Mid-Sized Schools'!M75-'Mid-Sized Schools'!M54 -> -4237934963
B46: Flagships | C46: ='Flagship Schools'!C75-'Flagship Schools'!C54 -> 0 | D46: ='Flagship Schools'!D75-'Flagship Schools'!D54 -> 0 | E46: ='Flagship Schools'!E75-'Flagship Schools'!E54 -> 0 | F46: ='Flagship Schools'!F75-'Flagship Schools'!F54 -> -76600000 | G46: ='Flagship Schools'!G75-'Flagship Schools'!G54 -> -1600000 | H46: ='Flagship Schools'!H75-'Flagship Schools'!H54 -> -63217588 | I46: ='Flagship Schools'!I75-'Flagship Schools'!I54 -> 29128068 | J46: ='Flagship Schools'!J75-'Flagship Schools'!J54 -> -15539414 | ... M46: ='Flagship Schools'!M75-'Flagship Schools'!M54 -> 128297876
B48: Property Value
B49: Mid-Sized / Flagship | C49: ='Mid-Sized Schools'!C59+'Flagship Schools'!C59 -> 36000000 | D49: ='Mid-Sized Schools'!D59+'Flagship Schools'!D59 -> 293500000 | E49: ='Mid-Sized Schools'!E59+'Flagship Schools'!E59 -> 594400000 | F49: ='Mid-Sized Schools'!F59+'Flagship Schools'!F59 -> 1593300000 | G49: ='Mid-Sized Schools'!G59+'Flagship Schools'!G59 -> 3080200000 | H49: ='Mid-Sized Schools'!H59+'Flagship Schools'!H59 -> 4507100000 | I49: ='Mid-Sized Schools'!I59+'Flagship Schools'!I59 -> 5718000000 | J49: ='Mid-Sized Schools'!J59+'Flagship Schools'!J59 -> 6868900000 | ... M49: ='Mid-Sized Schools'!M59+'Flagship Schools'!M59 -> 21325100000
B50: Cash Flows | C50: =SUM(C43:C46) -> 11218464 | D50: =SUM(D43:D46) -> -191884095 | E50: =SUM(E43:E46) -> -213612105 | F50: =SUM(F43:F46) -> -893267315 | G50: =SUM(G43:G46) -> -1384475950 | H50: =SUM(H43:H46) -> -1250929438 | I50: =SUM(I43:I46) -> -8.5103353e+08 | J50: =SUM(J43:J46) -> -5.9002891e+08 | ... M50: =SUM(M43:M46) -> -3529737087
...

Sheet Claude Cache
A1: ⚠️ SHEET RESERVED FOR =CLAUDE... FUNCTIONS. DO NOT EDIT! ⚠️
A2: Key | B2: Value | C2: Expiration

Sheet Virtual Schools
A1: TSA Virtual School | B1: Virtual School
B2: Description | C2: SY 2026 | D2: SY 2027 | E2: SY 2028 | F2: SY 2029 | G2: SY 2030 | H2: SY 2031 | I2: SY 2032 | J2: SY 2033 | K2: SY 2034 | L2: SY 2035 | M2: SY 2036
B3: Students | C3: 10000 | D3: 20000 | E3: 30000 | F3: 40000 | G3: 50000 | H3: 60000 | I3: 70000 | J3: 80000 | K3: 90000 | L3: 100000 | M3: 100000
B4: Tuition | C4: ='School Assumptions'!$B$2 -> 10474 | D4: ='School Assumptions'!$B$2 -> 10474 | E4: ='School Assumptions'!$B$2 -> 10474 | F4: ='School Assumptions'!$B$2 -> 10474 | G4: ='School Assumptions'!$B$2 -> 10474 | H4: ='School Assumptions'!$B$2 -> 10474 | I4: ='School Assumptions'!$B$2 -> 10474 | J4: ='School Assumptions'!$B$2 -> 10474 | ... M4: ='School Assumptions'!$B$2 -> 10474
B5: Organic Churn | C5: ='School Assumptions'!$B$9 -> 0.075 | D5: ='School Assumptions'!$B$9 -> 0.075 | E5: ='School Assumptions'!$B$9 -> 0.075 | F5: ='School Assumptions'!$B$9 -> 0.075 | G5: ='School Assumptions'!$B$9 -> 0.075 | H5: ='School Assumptions'!$B$9 -> 0.075 | I5: ='School Assumptions'!$B$9 -> 0.075 | J5: ='School Assumptions'!$B$9 -> 0.075 | ... M5: ='School Assumptions'!$B$9 -> 0.075
B6: Average Student Life | C6: ='School Assumptions'!$B$8 -> 2.5 | D6: ='School Assumptions'!$B$8 -> 2.5 | E6: ='School Assumptions'!$B$8 -> 2.5 | F6: ='School Assumptions'!$B$8 -> 2.5 | G6: ='School Assumptions'!$B$8 -> 2.5 | H6: ='School Assumptions'!$B$8 -> 2.5 | I6: ='School Assumptions'!$B$8 -> 2.5 | J6: ='School Assumptions'!$B$8 -> 2.5 | ... M6: ='School Assumptions'!$B$8 -> 2.5
B7: Tuition Revenue | C7: =C3*C4 -> 104740000 | D7: =D3*D4 -> 209480000 | E7: =E3*E4 -> 314220000 | F7: =F3*F4 -> 418960000 | G7: =G3*G4 -> 523700000 | H7: =H3*H4 -> 628440000 | I7: =I3*I4 -> 733180000 | J7: =J3*J4 -> 837920000 | ... M7: =M3*M4 -> 1047400000
B9: Total Students
B10: Beginning / End of Previous SY | C10: 0 | D10: =C14 -> 10000 | E10: =D14 -> 20000 | F10: =E14 -> 30000 | G10: =F14 -> 40000 | H10: =G14 -> 50000 | I10: =H14 -> 60000 | J10: =I14 -> 70000 | K10: =J14 -> 80000 | ... M10: =L14 -> 100000
B11: Organic Churn | C11: =-(C10*C5) -> 0 | D11: =ROUND(-(D10*D5),0) -> -750 | E11: =ROUND(-(E10*E5),0) -> -1500 | F11: =ROUND(-(F10*F5),0) -> -2250 | G11: =ROUND(-(G10*G5),0) -> -3000 | H11: =ROUND(-(H10*H5),0) -> -3750 | I11: =ROUND(-(I10*I5),0) -> -4500 | J11: =ROUND(-(J10*J5),0) -> -5250 | K11: =ROUND(-(K10*K5),0) -> -6000 | ... M11: =ROUND(-(M10*M5),0) -> -7500
B12: Rollover Churn | D12: =-C14/'School Assumptions'!$B$8 -> -4000 | E12: =-D14/'School Assumptions'!$B$8 -> -8000 | F12: =-E14/'School Assumptions'!$B$8 -> -12000 | G12: =-F14/'School Assumptions'!$B$8 -> -16000 | H12: =-G14/'School Assumptions'!$B$8 -> -20000 | I12: =-H14/'School Assumptions'!$B$8 -> -24000 | J12: =-I14/'School Assumptions'!$B$8 -> -28000 | K12: =-J14/'School Assumptions'!$B$8 -> -32000 | ... M12: =-L14/'School Assumptions'!$B$8 -> -40000
B13: New (at start of SY) | C13: =C14-(C10+C11) -> 10000 | D13: =D14-(D10+D11+D12) -> 14750 | E13: =E14-(E10+E11+E12) -> 19500 | F13: =F14-(F10+F11+F12) -> 24250 | G13: =G14-(G10+G11+G12) -> 29000 | H13: =H14-(H10+H11+H12) -> 33750 | I13: =I14-(I10+I11+I12) -> 38500 | J13: =J14-(J10+J11+J12) -> 43250 | K13: =K14-(K10+K11+K12) -> 48000 | ... M13: =M14-(M10+M11+M12) -> 47500
B14: Enrolled for SY | C14: =C3 -> 10000 | D14: =D3 -> 20000 | E14: =E3 -> 30000 | F14: =F3 -> 40000 | G14: =G3 -> 50000 | H14: =H3 -> 60000 | I14: =I3 -> 70000 | J14: =J3 -> 80000 | ... M14: =M3 -> 100000
B17: Expenses (per student)
B18: Headcount | C18: 3000 | D18: 3000 | E18: 3000 | F18: 3000 | G18: 3000 | H18: 3000 | I18: 3000 | J18: 3000 | K18: 3000 | L18: 3000 | M18: 3000
B19: Programs | C19: 1000 | D19: 1000 | E19: 1000 | F19: 1000 | G19: 1000 | H19: 1000 | I19: 1000 | J19: 1000 | K19: 1000 | L19: 1000 | M19: 1000
B20: Misc. Expense | C20: 750 | D20: 750 | E20: 750 | F20: 750 | G20: 750 | H20: 750 | I20: 750 | J20: 750 | K20: 750 | L20: 750 | M20: 750
B21: Timeback | C21: 2000 | D21: 2000 | E21: 2000 | F21: 2000 | G21: 2000 | H21: 2000 | I21: 2000 | J21: 2000 | K21: 2000 | L21: 2000 | M21: 2000
B22: Expenditures per Student | C22: =SUM(C18:C21) -> 6750 | D22: =SUM(D18:D21) -> 6750 | E22: =SUM(E18:E21) -> 6750 | F22: =SUM(F18:F21) -> 6750 | G22: =SUM(G18:G21) -> 6750 | H22: =SUM(H18:H21) -> 6750 | I22: =SUM(I18:I21) -> 6750 | J22: =SUM(J18:J21) -> 6750 | ... M22: =SUM(M18:M21) -> 6750
B23: Expenditures | C23: =C22*C14 -> 67500000 | D23: =D22*D14 -> 135000000 | E23: =E22*E14 -> 202500000 | F23: =F22*F14 -> 270000000 | G23: =G22*G14 -> 337500000 | H23: =H22*H14 -> 405000000 | I23: =I22*I14 -> 472500000 | J23: =J22*J14 -> 540000000 | ... M23: =M22*M14 -> 675000000
B25: Marketing
B26: Top of Funnel | C26: =C13*'School Assumptions'!$B$5 -> 5000000 | D26: =D13*'School Assumptions'!$B$5 -> 7375000 | E26: =E13*'School Assumptions'!$B$5 -> 9750000 | F26: =F13*'School Assumptions'!$B$5 -> 12125000 | G26: =G13*'School Assumptions'!$B$5 -> 14500000 | H26: =H13*'School Assumptions'!$B$5 -> 16875000 | I26: =I13*'School Assumptions'!$B$5 -> 19250000 | J26: =J13*'School Assumptions'!$B$5 -> 21625000 | ... M26: =M13*'School Assumptions'!$B$5 -> 23750000
B27: Bottom of Funnel | C27: =C13*'School Assumptions'!$B$6 -> 20000000 | D27: =D13*'School Assumptions'!$B$6 -> 29500000 | E27: =E13*'School Assumptions'!$B$6 -> 39000000 | F27: =F13*'School Assumptions'!$B$6 -> 48500000 | G27: =G13*'School Assumptions'!$B$6 -> 58000000 | H27: =H13*'School Assumptions'!$B$6 -> 67500000 | I27: =I13*'School Assumptions'!$B$6 -> 77000000 | J27: =J13*'School Assumptions'!$B$6 -> 86500000 | ... M27: =M13*'School Assumptions'!$B$6 -> 95000000
B28: Total Marketing | C28: =C26+C27 -> 25000000 | D28: =D26+D27 -> 36875000 | E28: =E26+E27 -> 48750000 | F28: =F26+F27 -> 60625000 | G28: =G26+G27 -> 72500000 | H28: =H26+H27 -> 84375000 | I28: =I26+I27 -> 96250000 | J28: =J26+J27 -> 108125000 | ... M28: =M26+M27 -> 118750000
B30: Pre-Tax Profit | C30: =C7-C23 -> 37240000 | D30: =D7-D23 -> 74480000 | E30: =E7-E23 -> 111720000 | F30: =F7-F23 -> 148960000 | G30: =G7-G23 -> 186200000 | H30: =H7-H23 -> 223440000 | I30: =I7-I23 -> 260680000 | J30: =J7-J23 -> 297920000 | ... M30: =M7-M23 -> 372400000
B32: Total Cash Flow | C32: =C30 -> 37240000 | D32: =D30 -> 74480000 | E32: =E30 -> 111720000 | F32: =F30 -> 148960000 | G32: =G30 -> 186200000 | H32: =H30 -> 223440000 | I32: =I30 -> 260680000 | J32: =J30 -> 297920000 | ... M32: =M30 -> 372400000

Sheet Microschools
B1: Microschool Forecast
B2: Description | C2: SY 2026 | D2: SY 2027 | E2: SY 2028 | F2: SY 2029 | G2: SY 2030 | H2: SY 2031 | I2: SY 2032 | J2: SY 2033 | K2: SY 2034 | L2: SY 2035 | M2: SY 2036
B4: No. of Schools | C4: 20 | D4: 60 | E4: 180 | F4: 540 | G4: =F4*3 -> 1620 | H4: 4000 | I4: 4,000 | J4: 4,000 | K4: 4,000 | L4: 4,000 | M4: 4,000
B5: Students per School | C5: 25 | D5: 25 | E5: 25 | F5: 25 | G5: 25 | H5: 25 | I5: 25 | J5: 25 | K5: 25 | L5: 25 | M5: 25
B6: Organic Churn | C6: ='School Assumptions'!$B$25 -> 0.075 | D6: ='School Assumptions'!$B$25 -> 0.075 | E6: ='School Assumptions'!$B$25 -> 0.075 | F6: ='School Assumptions'!$B$25 -> 0.075 | G6: ='School Assumptions'!$B$25 -> 0.075 | H6: ='School Assumptions'!$B$25 -> 0.075 | I6: ='School Assumptions'!$B$25 -> 0.075 | J6: ='School Assumptions'!$B$25 -> 0.075 | ... M6: ='School Assumptions'!$B$25 -> 0.075
B7: Average Student Life | C7: ='School Assumptions'!$B$24 -> 2.5 | D7: ='School Assumptions'!$B$24 -> 2.5 | E7: ='School Assumptions'!$B$24 -> 2.5 | F7: ='School Assumptions'!$B$24 -> 2.5 | G7: ='School Assumptions'!$B$24 -> 2.5 | H7: ='School Assumptions'!$B$24 -> 2.5 | I7: ='School Assumptions'!$B$24 -> 2.5 | J7: ='School Assumptions'!$B$24 -> 2.5 | ... M7: ='School Assumptions'!$B$24 -> 2.5
B9: Unit Economics / Student
B10: Tuition | C10: 15000 | D10: 15000 | E10: 15000 | F10: 15000 | G10: 15000 | H10: 15000 | I10: 15000 | J10: 15000 | K10: 15000 | L10: 15000 | M10: 15000
B11: Coach Salary | C11: 3750 | D11: 3750 | E11: 3750 | F11: 3750 | G11: 3750 | H11: 3750 | I11: 3750 | J11: 3750 | K11: 3750 | L11: 3750 | M11: 3750
B12: Real Estate | C12: 2500 | D12: 2500 | E12: 2500 | F12: 2500 | G12: 2500 | H12: 2500 | I12: 2500 | J12: 2500 | K12: 2500 | L12: 2500 | M12: 2500
B13: Life Skills Workshops | C13: 1000 | D13: 1000 | E13: 1000 | F13: 1000 | G13: 1000 | H13: 1000 | I13: 1000 | J13: 1000 | K13: 1000 | L13: 1000 | M13: 1000
B14: Misc Expenses (computer, etc.) | C14: 1250 | D14: 1250 | E14: 1250 | F14: 1250 | G14: 1250 | H14: 1250 | I14: 1250 | J14: 1250 | K14: 1250 | L14: 1250 | M14: 1250
B15: Timeback | C15: 3000 | D15: 3000 | E15: 3000 | F15: 3000 | G15: 3000 | H15: 3000 | I15: 3000 | J15: 3000 | K15: 3000 | L15: 3000 | M15: 3000
B16: Total Expenses | C16: =SUM(C11:C15) -> 11500 | D16: =SUM(D11:D15) -> 11500 | E16: =SUM(E11:E15) -> 11500 | F16: =SUM(F11:F15) -> 11500 | G16: =SUM(G11:G15) -> 11500 | H16: =SUM(H11:H15) -> 11500 | I16: =SUM(I11:I15) -> 11500 | J16: =SUM(J11:J15) -> 11500 | ... M16: =SUM(M11:M15) -> 11500
B18: EBITDA / Student | C18: =C10-C16 -> 3500 | D18: =D10-D16 -> 3500 | E18: =E10-E16 -> 3500 | F18: =F10-F16 -> 3500 | G18: =G10-G16 -> 3500 | H18: =H10-H16 -> 3500 | I18: =I10-I16 -> 3500 | J18: =J10-J16 -> 3500 | ... M18: =M10-M16 -> 3500
B19: EBITDA Margin | C19: =C18/C10 -> 0.23333333 | D19: =D18/D10 -> 0.23333333 | E19: =E18/E10 -> 0.23333333 | F19: =F18/F10 -> 0.23333333 | G19: =G18/G10 -> 0.23333333 | H19: =H18/H10 -> 0.23333333 | I19: =I18/I10 -> 0.23333333 | J19: =J18/J10 -> 0.23333333 | ... M19: =M18/M10 -> 0.23333333
B21: School Composition
B22: Existing Schools | C22: 6 | D22: =C24 -> 20 | E22: =D24 -> 60 | F22: =E24 -> 180 | G22: =F24 -> 540 | H22: =G24 -> 1620 | I22: =H24 -> 4000 | J22: =I24 -> 4,000 | K22: =J24 -> 4,000 | ... M22: =L24 -> 4,000
B23: New Schools | C23: =C4-C22 -> 14 | D23: =D4-D22 -> 40 | E23: =E4-E22 -> 120 | F23: =F4-F22 -> 360 | G23: =G4-G22 -> 1080 | H23: =H4-H22 -> 2380 | I23: =I4-I22 -> 0 | J23: =J4-J22 -> 0 | ... M23: =M4-M22 -> 0
B24: Total Schools | C24: =C4 -> 20 | D24: =D4 -> 60 | E24: =E4 -> 180 | F24: =F4 -> 540 | G24: =G4 -> 1620 | H24: =H4 -> 4000 | I24: =I4 -> 4,000 | J24: =J4 -> 4,000 | ... M24: =M4 -> 4,000
B26: Total Students
B27: Beginning / End of Previous SY | C27: 150 | D27: =C31 -> 395 | E27: =D31 -> 1200 | F27: =E31 -> 3600 | G27: =F31 -> 10800 | H27: =G31 -> 32400 | I27: =H31 -> 82150 | J27: =I31 -> 100000 | K27: =J31 -> 100000 | ... M27: =L31 -> 100000
B28: Organic Churn | C28: =ROUND(-C27*$C6,0) -> -11 | D28: =ROUND(-D27*$C6,0) -> -30 | E28: =ROUND(-E27*$C6,0) -> -90 | F28: =ROUND(-F27*$C6,0) -> -270 | G28: =ROUND(-G27*$C6,0) -> -810 | H28: =ROUND(-H27*$C6,0) -> -2430 | I28: =ROUND(-I27*$C6,0) -> -6161 | J28: =ROUND(-J27*$C6,0) -> -7500 | ... M28: =ROUND(-M27*$C6,0) -> -7500
B29: Rollover Churn | D29: =ROUND(-C31/'School Assumptions'!$B$24,0) -> -158 | E29: =ROUND(-D31/'School Assumptions'!$B$24,0) -> -480 | F29: =ROUND(-E31/'School Assumptions'!$B$24,0) -> -1440 | G29: =ROUND(-F31/'School Assumptions'!$B$24,0) -> -4320 | H29: =ROUND(-G31/'School Assumptions'!$B$24,0) -> -12960 | I29: =ROUND(-H31/'School Assumptions'!$B$24,0) -> -32860 | J29: =ROUND(-I31/'School Assumptions'!$B$24,0) -> -40000 | K29: =ROUND(-J31/'School Assumptions'!$B$24,0) -> -40000 | ... M29: =ROUND(-L31/'School Assumptions'!$B$24,0) -> -40000
B30: New (at start of SY) | C30: =C31-(C27+C28) -> 256 | D30: =D31-(D27+D28+D29) -> 993 | E30: =E31-(E27+E28+E29) -> 2970 | F30: =F31-(F27+F28+F29) -> 8910 | G30: =G31-(G27+G28+G29) -> 26730 | H30: =H31-(H27+H28+H29) -> 65140 | I30: =I31-(I27+I28+I29) -> 56871 | J30: =J31-(J27+J28+J29) -> 47500 | K30: =K31-(K27+K28+K29) -> 47500 | ... M30: =M31-(M27+M28+M29) -> 47500
B31: Enrolled for SY | C31: =(C22*C5)+(C23*'School Assumptions'!$B$21*C5) -> 395 | D31: =(D22*D5)+(D23*'School Assumptions'!$B$21*D5) -> 1200 | E31: =(E22*E5)+(E23*'School Assumptions'!$B$21*E5) -> 3600 | F31: =(F22*F5)+(F23*'School Assumptions'!$B$21*F5) -> 10800 | G31: =(G22*G5)+(G23*'School Assumptions'!$B$21*G5) -> 32400 | H31: =(H22*H5)+(H23*'School Assumptions'!$B$21*H5) -> 82150 | I31: =(I22*I5)+(I23*'School Assumptions'!$B$21*I5) -> 100000 | J31: =(J22*J5)+(J23*'School Assumptions'!$B$21*J5) -> 100000 | ... M31: =(M22*M5)+(M23*'School Assumptions'!$B$21*M5) -> 100000
B33: Tuition Revenue | C33: =C31*C10 -> 5925000 | D33: =D31*D10 -> 18000000 | E33: =E31*E10 -> 54000000 | F33: =F31*F10 -> 162000000 | G33: =G31*G10 -> 486000000 | H33: =H31*H10 -> 1232250000 | I33: =I31*I10 -> 1500000000 | J33: =J31*J10 -> 1500000000 | ... M33: =M31*M10 -> 1500000000
B34: Total Expenses | C34: =C16*C31 -> 4542500 | D34: =D16*D31 -> 13800000 | E34: =E16*E31 -> 41400000 | F34: =F16*F31 -> 124200000 | G34: =G16*G31 -> 372600000 | H34: =H16*H31 -> 944725000 | I34: =I16*I31 -> 1150000000 | J34: =J16*J31 -> 1150000000 | ... M34: =M16*M31 -> 1150000000
B35: EBITDA (ex-Marketing) | C35: =C33-C34 -> 1382500 | D35: =D33-D34 -> 4200000 | E35: =E33-E34 -> 12600000 | F35: =F33-F34 -> 37800000 | G35: =G33-G34 -> 113400000 | H35: =H33-H34 -> 287525000 | I35: =I33-I34 -> 350000000 | J35: =J33-J34 -> 350000000 | ... M35: =M33-M34 -> 350000000
B37: Marketing
B38: Top of Funnel | C38: ='School Assumptions'!$B$17*C30 -> 128000 | D38: ='School Assumptions'!$B$17*D30 -> 496500 | E38: ='School Assumptions'!$B$17*E30 -> 1485000 | F38: ='School Assumptions'!$B$17*F30 -> 4455000 | G38: ='School Assumptions'!$B$17*G30 -> 13365000 | H38: ='School Assumptions'!$B$17*H30 -> 32570000 | I38: ='School Assumptions'!$B$17*I30 -> 28435500 | J38: ='School Assumptions'!$B$17*J30 -> 23750000 | ... M38: ='School Assumptions'!$B$17*M30 -> 23750000
B39: Bottom of Funnel | C39: ='School Assumptions'!$B$18*C30 -> 640000 | D39: ='School Assumptions'!$B$18*D30 -> 2482500 | E39: ='School Assumptions'!$B$18*E30 -> 7425000 | F39: ='School Assumptions'!$B$18*F30 -> 22275000 | G39: ='School Assumptions'!$B$18*G30 -> 66825000 | H39: ='School Assumptions'!$B$18*H30 -> 162850000 | I39: ='School Assumptions'!$B$18*I30 -> 142177500 | J39: ='School Assumptions'!$B$18*J30 -> 118750000 | ... M39: ='School Assumptions'!$B$18*M30 -> 118750000
B40: Total Marketing | C40: =C38+C39 -> 768000 | D40: =D38+D39 -> 2979000 | E40: =E38+E39 -> 8910000 | F40: =F38+F39 -> 26730000 | G40: =G38+G39 -> 80190000 | H40: =H38+H39 -> 195420000 | I40: =I38+I39 -> 170613000 | J40: =J38+J39 -> 142500000 | ... M40: =M38+M39 -> 142500000
B42: EBITDA | C42: =C35-C40 -> 614500 | D42: =D35-D40 -> 1221000 | E42: =E35-E40 -> 3690000 | F42: =F35-F40 -> 11070000 | G42: =G35-G40 -> 33210000 | H42: =H35-H40 -> 92105000 | I42: =I35-I40 -> 179387000 | J42: =J35-J40 -> 207500000 | ... M42: =M35-M40 -> 207500000
B44: Total Cash Flow | C44: =C35-C40 -> 614500 | D44: =D35-D40 -> 1221000 | E44: =E35-E40 -> 3690000 | F44: =F35-F40 -> 11070000 | G44: =G35-G40 -> 33210000 | H44: =H35-H40 -> 92105000 | I44: =I35-I40 -> 179387000 | J44: =J35-J40 -> 207500000 | ... M44: =M35-M40 -> 207500000

Sheet Mid-Sized Schools
B1: Mid-Sized Schools
B2: Description | C2: SY 2026 | D2: SY 2027 | E2: SY 2028 | F2: SY 2029 | G2: SY 2030 | H2: SY 2031 | I2: SY 2032 | J2: SY 2033 | K2: SY 2034 | L2: SY 2035 | M2: SY 2036
B3: No. of Schools | C3: 2 | D3: 10 | E3: 20 | F3: 50 | G3: 100 | H3: 150 | I3: 200 | J3: 250 | K3: 400 | L3: 625 | M3: 800
B4: Students per School | C4: =('School Assumptions'!$B$29*'School Assumptions'!$B$46)+('School Assumptions'!$B$39*(1-'School Assumptions'!$B$46)) -> 700 | D4: =('School Assumptions'!$B$29*'School Assumptions'!$B$46)+('School Assumptions'!$B$39*(1-'School Assumptions'!$B$46)) -> 700 | E4: =('School Assumptions'!$B$29*'School Assumptions'!$B$46)+('School Assumptions'!$B$39*(1-'School Assumptions'!$B$46)) -> 700 | F4: =('School Assumptions'!$B$29*'School Assumptions'!$B$46)+('School Assumptions'!$B$39*(1-'School Assumptions'!$B$46)) -> 700 | G4: =('School Assumptions'!$B$29*'School Assumptions'!$B$46)+('School Assumptions'!$B$39*(1-'School Assumptions'!$B$46)) -> 700 | H4: =('School Assumptions'!$B$29*'School Assumptions'!$B$46)+('School Assumptions'!$B$39*(1-'School Assumptions'!$B$46)) -> 700 | I4: =('School Assumptions'!$B$29*'School Assumptions'!$B$46)+('School Assumptions'!$B$39*(1-'School Assumptions'!$B$46)) -> 700 | J4: =('School Assumptions'!$B$29*'School Assumptions'!$B$46)+('School Assumptions'!$B$39*(1-'School Assumptions'!$B$46)) -> 700 | ... M4: =('School Assumptions'!$B$29*'School Assumptions'!$B$46)+('School Assumptions'!$B$39*(1-'School Assumptions'!$B$46)) -> 700
B5: Organic Churn | C5: ='School Assumptions'!$B$55 -> 0.075 | D5: ='School Assumptions'!$B$55 -> 0.075 | E5: ='School Assumptions'!$B$55 -> 0.075 | F5: ='School Assumptions'!$B$55 -> 0.075 | G5: ='School Assumptions'!$B$55 -> 0.075 | H5: ='School Assumptions'!$B$55 -> 0.075 | I5: ='School Assumptions'!$B$55 -> 0.075 | J5: ='School Assumptions'!$B$55 -> 0.075 | ... M5: ='School Assumptions'!$B$55 -> 0.075
B6: Average Student Life | C6: ='School Assumptions'!$B$54 -> 4.5 | D6: ='School Assumptions'!$B$54 -> 4.5 | E6: ='School Assumptions'!$B$54 -> 4.5 | F6: ='School Assumptions'!$B$54 -> 4.5 | G6: ='School Assumptions'!$B$54 -> 4.5 | H6: ='School Assumptions'!$B$54 -> 4.5 | I6: ='School Assumptions'!$B$54 -> 4.5 | J6: ='School Assumptions'!$B$54 -> 4.5 | ... M6: ='School Assumptions'!$B$54 -> 4.5
B8: Unit Economics / Student
B9: Tuition | C9: =('School Assumptions'!$B$35*'School Assumptions'!$B$46)+('School Assumptions'!$B$43*(1-'School Assumptions'!$B$46)) -> 25000 | D9: =('School Assumptions'!$B$35*'School Assumptions'!$B$46)+('School Assumptions'!$B$43*(1-'School Assumptions'!$B$46)) -> 25000 | E9: =('School Assumptions'!$B$35*'School Assumptions'!$B$46)+('School Assumptions'!$B$43*(1-'School Assumptions'!$B$46)) -> 25000 | F9: =('School Assumptions'!$B$35*'School Assumptions'!$B$46)+('School Assumptions'!$B$43*(1-'School Assumptions'!$B$46)) -> 25000 | G9: =('School Assumptions'!$B$35*'School Assumptions'!$B$46)+('School Assumptions'!$B$43*(1-'School Assumptions'!$B$46)) -> 25000 | H9: =('School Assumptions'!$B$35*'School Assumptions'!$B$46)+('School Assumptions'!$B$43*(1-'School Assumptions'!$B$46)) -> 25000 | I9: =('School Assumptions'!$B$35*'School Assumptions'!$B$46)+('School Assumptions'!$B$43*(1-'School Assumptions'!$B$46)) -> 25000 | J9: =('School Assumptions'!$B$35*'School Assumptions'!$B$46)+('School Assumptions'!$B$43*(1-'School Assumptions'!$B$46)) -> 25000 | ... M9: =('School Assumptions'!$B$35*'School Assumptions'!$B$46)+('School Assumptions'!$B$43*(1-'School Assumptions'!$B$46)) -> 25000
B10: Headcount | C10: =(('Headcount Assumptions'!$D$11+'Headcount Assumptions'!$D$12)*'School Assumptions'!$B$46)+(('Headcount Assumptions'!$D$27+'Headcount Assumptions'!$D$28)*(1-'School Assumptions'!$B$46)) -> 5773 | D10: =(('Headcount Assumptions'!$D$11+'Headcount Assumptions'!$D$12)*'School Assumptions'!$B$46)+(('Headcount Assumptions'!$D$27+'Headcount Assumptions'!$D$28)*(1-'School Assumptions'!$B$46)) -> 5773 | E10: =(('Headcount Assumptions'!$D$11+'Headcount Assumptions'!$D$12)*'School Assumptions'!$B$46)+(('Headcount Assumptions'!$D$27+'Headcount Assumptions'!$D$28)*(1-'School Assumptions'!$B$46)) -> 5773 | F10: =(('Headcount Assumptions'!$D$11+'Headcount Assumptions'!$D$12)*'School Assumptions'!$B$46)+(('Headcount Assumptions'!$D$27+'Headcount Assumptions'!$D$28)*(1-'School Assumptions'!$B$46)) -> 5773 | G10: =(('Headcount Assumptions'!$D$11+'Headcount Assumptions'!$D$12)*'School Assumptions'!$B$46)+(('Headcount Assumptions'!$D$27+'Headcount Assumptions'!$D$28)*(1-'School Assumptions'!$B$46)) -> 5773 | H10: =(('Headcount Assumptions'!$D$11+'Headcount Assumptions'!$D$12)*'School Assumptions'!$B$46)+(('Headcount Assumptions'!$D$27+'Headcount Assumptions'!$D$28)*(1-'School Assumptions'!$B$46)) -> 5773 | I10: =(('Headcount Assumptions'!$D$11+'Headcount Assumptions'!$D$12)*'School Assumptions'!$B$46)+(('Headcount Assumptions'!$D$27+'Headcount Assumptions'!$D$28)*(1-'School Assumptions'!$B$46)) -> 5773 | J10: =(('Headcount Assumptions'!$D$11+'Headcount Assumptions'!$D$12)*'School Assumptions'!$B$46)+(('Headcount Assumptions'!$D$27+'Headcount Assumptions'!$D$28)*(1-'School Assumptions'!$B$46)) -> 5773 | ... M10: =(('Headcount Assumptions'!$D$11+'Headcount Assumptions'!$D$12)*'School Assumptions'!$B$46)+(('Headcount Assumptions'!$D$27+'Headcount Assumptions'!$D$28)*(1-'School Assumptions'!$B$46)) -> 5773
B11: Programs / Motivation | C11: ='Headcount Assumptions'!$D$13+'Headcount Assumptions'!$D$14 -> 2500 | D11: ='Headcount Assumptions'!$D$13+'Headcount Assumptions'!$D$14 -> 2500 | E11: ='Headcount Assumptions'!$D$13+'Headcount Assumptions'!$D$14 -> 2500 | F11: ='Headcount Assumptions'!$D$13+'Headcount Assumptions'!$D$14 -> 2500 | G11: ='Headcount Assumptions'!$D$13+'Headcount Assumptions'!$D$14 -> 2500 | H11: ='Headcount Assumptions'!$D$13+'Headcount Assumptions'!$D$14 -> 2500 | I11: ='Headcount Assumptions'!$D$13+'Headcount Assumptions'!$D$14 -> 2500 | J11: ='Headcount Assumptions'!$D$13+'Headcount Assumptions'!$D$14 -> 2500 | ... M11: ='Headcount Assumptions'!$D$13+'Headcount Assumptions'!$D$14 -> 2500
B12: Misc Expenses (computer, etc.) | C12: 1250 | D12: 1250 | E12: 1250 | F12: 1250 | G12: 1250 | H12: 1250 | I12: 1250 | J12: 1250 | K12: 1250 | L12: 1250 | M12: 1250
B13: Timeback | C13: 5000 | D13: 5000 | E13: 5000 | F13: 5000 | G13: 5000 | H13: 5000 | I13: 5000 | J13: 5000 | K13: 5000 | L13: 5000 | M13: 5000
B14: Total Expenses | C14: =SUM(C10:C13) -> 14523 | D14: =SUM(D10:D13) -> 14523 | E14: =SUM(E10:E13) -> 14523 | F14: =SUM(F10:F13) -> 14523 | G14: =SUM(G10:G13) -> 14523 | H14: =SUM(H10:H13) -> 14523 | I14: =SUM(I10:I13) -> 14523 | J14: =SUM(J10:J13) -> 14523 | ... M14: =SUM(M10:M13) -> 14523
B15: Profit (pre-Facilities) | C15: =C9-C14 -> 10477 | D15: =D9-D14 -> 10477 | E15: =E9-E14 -> 10477 | F15: =F9-F14 -> 10477 | G15: =G9-G14 -> 10477 | H15: =H9-H14 -> 10477 | I15: =I9-I14 -> 10477 | J15: =J9-J14 -> 10477 | ... M15: =M9-M14 -> 10477
B16: Margin | C16: =C15/C9 -> 0.41908 | D16: =D15/D9 -> 0.41908 | E16: =E15/E9 -> 0.41908 | F16: =F15/F9 -> 0.41908 | G16: =G15/G9 -> 0.41908 | H16: =H15/H9 -> 0.41908 | I16: =I15/I9 -> 0.41908 | J16: =J15/J9 -> 0.41908 | ... M16: =M15/M9 -> 0.41908
B18: School Composition
B19: Existing Schools | C19: 0 | D19: =C24 -> 2 | E19: =D24 -> 10 | F19: =E24 -> 20 | G19: =F24 -> 50 | H19: =G24 -> 100 | I19: =H24 -> 150 | J19: =I24 -> 200 | K19: =J24 -> 250 | ... M19: =L24 -> 625
B20: New Schools | C20: =C24-C19 -> 2 | D20: =D24-D19 -> 8 | E20: =E24-E19 -> 10 | F20: =F24-F19 -> 30 | G20: =G24-G19 -> 50 | H20: =H24-H19 -> 50 | I20: =I24-I19 -> 50 | J20: =J24-J19 -> 50 | ... M20: =M24-M19 -> 175
B21: 1-Year Old Schools | D21: =C20 -> 2 | E21: =D20 -> 8 | F21: =E20 -> 10 | G21: =F20 -> 30 | H21: =G20 -> 50 | I21: =H20 -> 50 | J21: =I20 -> 50 | K21: =J20 -> 50 | ... M21: =L20 -> 225
B22: 2-Year Old Schools | D22: =C21 | E22: =D21 -> 2 | F22: =E21 -> 8 | G22: =F21 -> 10 | H22: =G21 -> 30 | I22: =H21 -> 50 | J22: =I21 -> 50 | K22: =J21 -> 50 | ... M22: =L21 -> 150
B23: 3-Year Old Schools | D23: =C22 | E23: =D22 | F23: =E22 -> 2 | G23: =F22+F23 -> 10 | H23: =G22+G23 -> 20 | I23: =H22+H23 -> 50 | J23: =I22+I23 -> 100 | K23: =J22+J23 -> 150 | L23: =K22+K23 -> 200 | M23: =L22+L23 -> 250
B24: Total Schools | C24: 2 | D24: =D3 -> 10 | E24: =E3 -> 20 | F24: =F3 -> 50 | G24: =G3 -> 100 | H24: =H3 -> 150 | I24: =I3 -> 200 | J24: =J3 -> 250 | K24: =K3 -> 400 | ... M24: =M3 -> 800
B26: Total Students
B27: Beginning / End of Previous SY | C27: 40 | D27: =C31 -> 40 | E27: =D31 -> 462 | F27: =E31 -> 2786 | G27: =F31 -> 7462 | H27: =G31 -> 18620 | I27: =H31 -> 39620 | J27: =I31 -> 70000 | K27: =J31 -> 105000 | ... M27: =L31 -> 198100
B28: Organic Churn | C28: =ROUND(-C27*$C5,0) -> -3 | D28: =ROUND(-D27*$C5,0) -> -3 | E28: =ROUND(-E27*$C5,0) -> -35 | F28: =ROUND(-F27*$C5,0) -> -209 | G28: =ROUND(-G27*$C5,0) -> -560 | H28: =ROUND(-H27*$C5,0) -> -1397 | I28: =ROUND(-I27*$C5,0) -> -2972 | J28: =ROUND(-J27*$C5,0) -> -5250 | ... M28: =ROUND(-M27*$C5,0) -> -14858
B29: Rollover Churn | D29: =ROUND(-C31/'School Assumptions'!$B$54,0) -> -9 | E29: =ROUND(-D31/'School Assumptions'!$B$54,0) -> -103 | F29: =ROUND(-E31/'School Assumptions'!$B$54,0) -> -619 | G29: =ROUND(-F31/'School Assumptions'!$B$54,0) -> -1658 | H29: =ROUND(-G31/'School Assumptions'!$B$54,0) -> -4138 | I29: =ROUND(-H31/'School Assumptions'!$B$54,0) -> -8804 | J29: =ROUND(-I31/'School Assumptions'!$B$54,0) -> -15556 | K29: =ROUND(-J31/'School Assumptions'!$B$54,0) -> -23333 | ... M29: =ROUND(-L31/'School Assumptions'!$B$54,0) -> -44022
B30: New (at start of SY) | C30: =C31-(C27+C28) -> 3 | D30: =D31-(D27+D28+D29) -> 434 | E30: =E31-(E27+E28+E29) -> 2462 | F30: =F31-(F27+F28+F29) -> 5504 | G30: =G31-(G27+G28+G29) -> 13376 | H30: =H31-(H27+H28+H29) -> 26535 | I30: =I31-(I27+I28+I29) -> 42156 | J30: =J31-(J27+J28+J29) -> 55806 | K30: =K31-(K27+K28+K29) -> 66208 | ... M30: =M31-(M27+M28+M29) -> 158105
B31: Enrolled for SY | C31: =MAX(C27,(C4*(C21*'School Assumptions'!$B$50)+(C22*'School Assumptions'!$B$51)+(C23*'School Assumptions'!$B$52)+(C20*'School Assumptions'!$B$49))) -> 40 | D31: =D4*((D21*'School Assumptions'!$B$50)+(D22*'School Assumptions'!$B$51)+(D23*'School Assumptions'!$B$52)+(D20*'School Assumptions'!$B$49)) -> 462 | E31: =E4*((E21*'School Assumptions'!$B$50)+(E22*'School Assumptions'!$B$51)+(E23*'School Assumptions'!$B$52)+(E20*'School Assumptions'!$B$49)) -> 2786 | F31: =F4*((F21*'School Assumptions'!$B$50)+(F22*'School Assumptions'!$B$51)+(F23*'School Assumptions'!$B$52)+(F20*'School Assumptions'!$B$49)) -> 7462 | G31: =G4*((G21*'School Assumptions'!$B$50)+(G22*'School Assumptions'!$B$51)+(G23*'School Assumptions'!$B$52)+(G20*'School Assumptions'!$B$49)) -> 18620 | H31: =H4*((H21*'School Assumptions'!$B$50)+(H22*'School Assumptions'!$B$51)+(H23*'School Assumptions'!$B$52)+(H20*'School Assumptions'!$B$49)) -> 39620 | I31: =I4*((I21*'School Assumptions'!$B$50)+(I22*'School Assumptions'!$B$51)+(I23*'School Assumptions'!$B$52)+(I20*'School Assumptions'!$B$49)) -> 70000 | J31: =J4*((J21*'School Assumptions'!$B$50)+(J22*'School Assumptions'!$B$51)+(J23*'School Assumptions'!$B$52)+(J20*'School Assumptions'!$B$49)) -> 105000 | K31: =K4*((K21*'School Assumptions'!$B$50)+(K22*'School Assumptions'!$B$51)+(K23*'School Assumptions'!$B$52)+(K20*'School Assumptions'!$B$49)) -> 140000 | ... M31: =M4*((M21*'School Assumptions'!$B$50)+(M22*'School Assumptions'!$B$51)+(M23*'School Assumptions'!$B$52)+(M20*'School Assumptions'!$B$49)) -> 297325
B33: Total Tuition Revenue | C33: =C31*C9 -> 1000000 | D33: =D31*D9 -> 11550000 | E33: =E31*E9 -> 69650000 | F33: =F31*F9 -> 186550000 | G33: =G31*G9 -> 465500000 | H33: =H31*H9 -> 990500000 | I33: =I31*I9 -> 1750000000 | J33: =J31*J9 -> 2625000000 | ... M33: =M31*M9 -> 7433125000
B35: Expenses (per student)
B36: Headcount | C36: ='Headcount Assumptions'!$F$11 -> 5232.5 | D36: ='Headcount Assumptions'!$F$11 -> 5232.5 | E36: ='Headcount Assumptions'!$F$11 -> 5232.5 | F36: ='Headcount Assumptions'!$F$11 -> 5232.5 | G36: ='Headcount Assumptions'!$F$11 -> 5232.5 | H36: ='Headcount Assumptions'!$F$11 -> 5232.5 | I36: ='Headcount Assumptions'!$F$11 -> 5232.5 | J36: ='Headcount Assumptions'!$F$11 -> 5232.5 | ... M36: ='Headcount Assumptions'!$F$11 -> 5232.5
B37: Programs | C37: ='Headcount Assumptions'!$F$13+'Headcount Assumptions'!$F$14 -> 3000 | D37: ='Headcount Assumptions'!$F$13+'Headcount Assumptions'!$F$14 -> 3000 | E37: ='Headcount Assumptions'!$F$13+'Headcount Assumptions'!$F$14 -> 3000 | F37: ='Headcount Assumptions'!$F$13+'Headcount Assumptions'!$F$14 -> 3000 | G37: ='Headcount Assumptions'!$F$13+'Headcount Assumptions'!$F$14 -> 3000 | H37: ='Headcount Assumptions'!$F$13+'Headcount Assumptions'!$F$14 -> 3000 | I37: ='Headcount Assumptions'!$F$13+'Headcount Assumptions'!$F$14 -> 3000 | J37: ='Headcount Assumptions'!$F$13+'Headcount Assumptions'!$F$14 -> 3000 | ... M37: ='Headcount Assumptions'!$F$13+'Headcount Assumptions'!$F$14 -> 3000
B38: Misc. Expense | C38: 1500 | D38: 1500 | E38: 1500 | F38: 1500 | G38: 1500 | H38: 1500 | I38: 1500 | J38: 1500 | K38: 1500 | L38: 1500 | M38: 1500
B39: Timeback | C39: 5000 | D39: 5000 | E39: 5000 | F39: 5000 | G39: 5000 | H39: 5000 | I39: 5000 | J39: 5000 | K39: 5000 | L39: 5000 | M39: 5000
B40: Expenditures per Student | C40: =SUM(C36:C39) -> 14732.5 | D40: =SUM(D36:D39) -> 14732.5 | E40: =SUM(E36:E39) -> 14732.5 | F40: =SUM(F36:F39) -> 14732.5 | G40: =SUM(G36:G39) -> 14732.5 | H40: =SUM(H36:H39) -> 14732.5 | I40: =SUM(I36:I39) -> 14732.5 | J40: =SUM(J36:J39) -> 14732.5 | ... M40: =SUM(M36:M39) -> 14732.5
B41: Total Expenditures | C41: =C31*C40 -> 589300 | D41: =D31*D40 -> 6806415 | E41: =E31*E40 -> 41044745 | F41: =F31*F40 -> 109933915 | G41: =G31*G40 -> 274319150 | H41: =H31*H40 -> 583701650 | I41: =I31*I40 -> 1031275000 | J41: =J31*J40 -> 1546912500 | ... M41: =M31*M40 -> 4380340563
B43: Profit (ex-Facilities) | C43: =C33-C41 -> 410700 | D43: =D33-D41 -> 4743585 | E43: =E33-E41 -> 28605255 | F43: =F33-F41 -> 76616085 | G43: =G33-G41 -> 191180850 | H43: =H33-H41 -> 406798350 | I43: =I33-I41 -> 718725000 | J43: =J33-J41 -> 1078087500 | ... M43: =M33-M41 -> 3052784438
B45: Facilities Costs
B46: Purchases | C46: 0 | D46: =D20*((('School Assumptions'!$B$30*'School Assumptions'!$B$46)+('School Assumptions'!$B$40*(1-'School Assumptions'!$B$46)))) -> 44000000 | E46: =E20*((('School Assumptions'!$B$30*'School Assumptions'!$B$46)+('School Assumptions'!$B$40*(1-'School Assumptions'!$B$46)))) -> 55000000 | F46: =F20*((('School Assumptions'!$B$30*'School Assumptions'!$B$46)+('School Assumptions'!$B$40*(1-'School Assumptions'!$B$46)))) -> 165000000 | G46: =G20*((('School Assumptions'!$B$30*'School Assumptions'!$B$46)+('School Assumptions'!$B$40*(1-'School Assumptions'!$B$46)))) -> 275000000 | H46: =H20*((('School Assumptions'!$B$30*'School Assumptions'!$B$46)+('School Assumptions'!$B$40*(1-'School Assumptions'!$B$46)))) -> 275000000 | I46: =I20*((('School Assumptions'!$B$30*'School Assumptions'!$B$46)+('School Assumptions'!$B$40*(1-'School Assumptions'!$B$46)))) -> 275000000 | J46: =J20*((('School Assumptions'!$B$30*'School Assumptions'!$B$46)+('School Assumptions'!$B$40*(1-'School Assumptions'!$B$46)))) -> 275000000 | K46: =K20*((('School Assumptions'!$B$30*'School Assumptions'!$B$46)+('School Assumptions'!$B$40*(1-'School Assumptions'!$B$46)))) -> 825000000 | ... M46: =M20*((('School Assumptions'!$B$30*'School Assumptions'!$B$46)+('School Assumptions'!$B$40*(1-'School Assumptions'!$B$46)))) -> 962500000
B47: Capex | C47: 25000000 | D47: =D20*((('School Assumptions'!$B$31*'School Assumptions'!$B$46)+('School Assumptions'!$B$41*(1-'School Assumptions'!$B$46)))) -> 216000000 | E47: =E20*((('School Assumptions'!$B$31*'School Assumptions'!$B$46)+('School Assumptions'!$B$41*(1-'School Assumptions'!$B$46)))) -> 270000000 | F47: =F20*((('School Assumptions'!$B$31*'School Assumptions'!$B$46)+('School Assumptions'!$B$41*(1-'School Assumptions'!$B$46)))) -> 810000000 | G47: =G20*((('School Assumptions'!$B$31*'School Assumptions'!$B$46)+('School Assumptions'!$B$41*(1-'School Assumptions'!$B$46)))) -> 1350000000 | H47: =H20*((('School Assumptions'!$B$31*'School Assumptions'!$B$46)+('School Assumptions'!$B$41*(1-'School Assumptions'!$B$46)))) -> 1350000000 | I47: =I20*((('School Assumptions'!$B$31*'School Assumptions'!$B$46)+('School Assumptions'!$B$41*(1-'School Assumptions'!$B$46)))) -> 1350000000 | J47: =J20*((('School Assumptions'!$B$31*'School Assumptions'!$B$46)+('School Assumptions'!$B$41*(1-'School Assumptions'!$B$46)))) -> 1350000000 | K47: =K20*((('School Assumptions'!$B$31*'School Assumptions'!$B$46)+('School Assumptions'!$B$41*(1-'School Assumptions'!$B$46)))) -> 4050000000 | ... M47: =M20*((('School Assumptions'!$B$31*'School Assumptions'!$B$46)+('School Assumptions'!$B$41*(1-'School Assumptions'!$B$46)))) -> 4725000000
...

Sheet Flagship Schools
B1: Flagship Schools
B2: Description | C2: SY 2026 | D2: SY 2027 | E2: SY 2028 | F2: SY 2029 | G2: SY 2030 | H2: SY 2031 | I2: SY 2032 | J2: SY 2033 | K2: SY 2034 | L2: SY 2035 | M2: SY 2036
B3: No. of Schools | C3: 0 | D3: 0 | E3: 0 | F3: 1 | G3: 1 | H3: 2 | I3: 2 | J3: 3 | K3: 3 | L3: 4 | M3: 4
B4: Students per School | C4: ='School Assumptions'!$B$65 -> 1500 | D4: ='School Assumptions'!$B$65 -> 1500 | E4: ='School Assumptions'!$B$65 -> 1500 | F4: ='School Assumptions'!$B$65 -> 1500 | G4: ='School Assumptions'!$B$65 -> 1500 | H4: ='School Assumptions'!$B$65 -> 1500 | I4: ='School Assumptions'!$B$65 -> 1500 | J4: ='School Assumptions'!$B$65 -> 1500 | ... M4: ='School Assumptions'!$B$65 -> 1500
B5: Organic Churn | C5: ='School Assumptions'!$B$79 -> 0.075 | D5: ='School Assumptions'!$B$79 -> 0.075 | E5: ='School Assumptions'!$B$79 -> 0.075 | F5: ='School Assumptions'!$B$79 -> 0.075 | G5: ='School Assumptions'!$B$79 -> 0.075 | H5: ='School Assumptions'!$B$79 -> 0.075 | I5: ='School Assumptions'!$B$79 -> 0.075 | J5: ='School Assumptions'!$B$79 -> 0.075 | ... M5: ='School Assumptions'!$B$79 -> 0.075
B6: Average Student Life | C6: ='School Assumptions'!$B$78 -> 6.5 | D6: ='School Assumptions'!$B$78 -> 6.5 | E6: ='School Assumptions'!$B$78 -> 6.5 | F6: ='School Assumptions'!$B$78 -> 6.5 | G6: ='School Assumptions'!$B$78 -> 6.5 | H6: ='School Assumptions'!$B$78 -> 6.5 | I6: ='School Assumptions'!$B$78 -> 6.5 | J6: ='School Assumptions'!$B$78 -> 6.5 | ... M6: ='School Assumptions'!$B$78 -> 6.5
B8: Unit Economics / Student
B9: Tuition | C9: ='School Assumptions'!$B$64 -> 50000 | D9: ='School Assumptions'!$B$64 -> 50000 | E9: ='School Assumptions'!$B$64 -> 50000 | F9: ='School Assumptions'!$B$64 -> 50000 | G9: ='School Assumptions'!$B$64 -> 50000 | H9: ='School Assumptions'!$B$64 -> 50000 | I9: ='School Assumptions'!$B$64 -> 50000 | J9: ='School Assumptions'!$B$64 -> 50000 | ... M9: ='School Assumptions'!$B$64 -> 50000
B10: Headcount | C10: ='Headcount Assumptions'!$C$43+'Headcount Assumptions'!$C$44 -> 5244 | D10: ='Headcount Assumptions'!$C$43+'Headcount Assumptions'!$C$44 -> 5244 | E10: ='Headcount Assumptions'!$C$43+'Headcount Assumptions'!$C$44 -> 5244 | F10: ='Headcount Assumptions'!$C$43+'Headcount Assumptions'!$C$44 -> 5244 | G10: ='Headcount Assumptions'!$C$43+'Headcount Assumptions'!$C$44 -> 5244 | H10: ='Headcount Assumptions'!$C$43+'Headcount Assumptions'!$C$44 -> 5244 | I10: ='Headcount Assumptions'!$C$43+'Headcount Assumptions'!$C$44 -> 5244 | J10: ='Headcount Assumptions'!$C$43+'Headcount Assumptions'!$C$44 -> 5244 | ... M10: ='Headcount Assumptions'!$C$43+'Headcount Assumptions'!$C$44 -> 5244
B11: Programs / Motivation | C11: ='Headcount Assumptions'!$D$13+'Headcount Assumptions'!$D$14 -> 2500 | D11: ='Headcount Assumptions'!$D$13+'Headcount Assumptions'!$D$14 -> 2500 | E11: ='Headcount Assumptions'!$D$13+'Headcount Assumptions'!$D$14 -> 2500 | F11: ='Headcount Assumptions'!$D$13+'Headcount Assumptions'!$D$14 -> 2500 | G11: ='Headcount Assumptions'!$D$13+'Headcount Assumptions'!$D$14 -> 2500 | H11: ='Headcount Assumptions'!$D$13+'Headcount Assumptions'!$D$14 -> 2500 | I11: ='Headcount Assumptions'!$D$13+'Headcount Assumptions'!$D$14 -> 2500 | J11: ='Headcount Assumptions'!$D$13+'Headcount Assumptions'!$D$14 -> 2500 | ... M11: ='Headcount Assumptions'!$D$13+'Headcount Assumptions'!$D$14 -> 2500
B12: Misc Expenses (computer, etc.) | C12: 1250 | D12: 1250 | E12: 1250 | F12: 1250 | G12: 1250 | H12: 1250 | I12: 1250 | J12: 1250 | K12: 1250 | L12: 1250 | M12: 1250
B13: Timeback | C13: 10000 | D13: 10000 | E13: 10000 | F13: 10000 | G13: 10000 | H13: 10000 | I13: 10000 | J13: 10000 | K13: 10000 | L13: 10000 | M13: 10000
B14: Total Expenses | C14: =SUM(C10:C13) -> 18994 | D14: =SUM(D10:D13) -> 18994 | E14: =SUM(E10:E13) -> 18994 | F14: =SUM(F10:F13) -> 18994 | G14: =SUM(G10:G13) -> 18994 | H14: =SUM(H10:H13) -> 18994 | I14: =SUM(I10:I13) -> 18994 | J14: =SUM(J10:J13) -> 18994 | ... M14: =SUM(M10:M13) -> 18994
B15: Profit (pre-Facilities) | C15: =C9-C14 -> 31006 | D15: =D9-D14 -> 31006 | E15: =E9-E14 -> 31006 | F15: =F9-F14 -> 31006 | G15: =G9-G14 -> 31006 | H15: =H9-H14 -> 31006 | I15: =I9-I14 -> 31006 | J15: =J9-J14 -> 31006 | ... M15: =M9-M14 -> 31006
B16: Margin | C16: =C15/C9 -> 0.62012 | D16: =D15/D9 -> 0.62012 | E16: =E15/E9 -> 0.62012 | F16: =F15/F9 -> 0.62012 | G16: =G15/G9 -> 0.62012 | H16: =H15/H9 -> 0.62012 | I16: =I15/I9 -> 0.62012 | J16: =J15/J9 -> 0.62012 | ... M16: =M15/M9 -> 0.62012
B18: School Composition
B19: Existing Schools | C19: 0 | D19: =C25 -> 0 | E19: =D25 -> 0 | F19: =E25 -> 0 | G19: =F25 -> 1 | H19: =G25 -> 1 | I19: =H25 -> 2 | J19: =I25 -> 2 | K19: =J25 -> 3 | ... M19: =L25 -> 4
B20: New Schools | C20: =C25-C19 -> 0 | D20: =D25-D19 -> 0 | E20: =E25-E19 -> 0 | F20: =F25-F19 -> 1 | G20: =G25-G19 -> 0 | H20: =H25-H19 -> 1 | I20: =I25-I19 -> 0 | J20: =J25-J19 -> 1 | ... M20: =M25-M19 -> 0
B21: 1-Year Old Schools | D21: =C20 -> 0 | E21: =D20 -> 0 | F21: =E20 -> 0 | G21: =F20 -> 1 | H21: =G20 -> 0 | I21: =H20 -> 1 | J21: =I20 -> 0 | K21: =J20 -> 1 | ... M21: =L20 -> 1
B22: 2-Year Old Schools | D22: =C21 | E22: =D21 -> 0 | F22: =E21 -> 0 | G22: =F21 -> 0 | H22: =G21 -> 1 | I22: =H21 -> 0 | J22: =I21 -> 1 | K22: =J21 -> 0 | ... M22: =L21 -> 0
B23: 3-Year Old Schools | D23: =C22 | E23: =D22 | F23: =E22 -> 0 | G23: =F22 -> 0 | H23: =G22 -> 0 | I23: =H22 -> 1 | J23: =I22 -> 0 | K23: =J22 -> 1 | ... M23: =L22 -> 1
B24: 4-Year Old Schools | J24: =I23 -> 1 | K24: =J24+J23 -> 1 | L24: =K24+K23 -> 2 | M24: =L24+L23 -> 2
B25: Total Schools | C25: =C3 -> 0 | D25: =D3 -> 0 | E25: =E3 -> 0 | F25: =F3 -> 1 | G25: =G3 -> 1 | H25: =H3 -> 2 | I25: =I3 -> 2 | J25: =J3 -> 3 | ... M25: =M3 -> 4
B27: Total Students
B28: Beginning / End of Previous SY | C28: 0 | D28: =C32 -> 0 | E28: =D32 -> 0 | F28: =E32 -> 0 | G28: =F32 -> 0 | H28: =G32 -> 0 | I28: =H32 -> 495 | J28: =I32 -> 1005 | K28: =J32 -> 1995 | ... M28: =L32 -> 3495
B29: Organic Churn | C29: =ROUND(-C28*$C5,0) -> 0 | D29: =ROUND(-D28*$C5,0) -> 0 | E29: =ROUND(-E28*$C5,0) -> 0 | F29: =ROUND(-F28*$C5,0) -> 0 | G29: =ROUND(-G28*$C5,0) -> 0 | H29: =ROUND(-H28*$C5,0) -> 0 | I29: =ROUND(-I28*$C5,0) -> -37 | J29: =ROUND(-J28*$C5,0) -> -75 | ... M29: =ROUND(-M28*$C5,0) -> -262
B30: Rollover Churn | D30: =ROUND(-C32/'School Assumptions'!$B$78,0) -> 0 | E30: =-D32/'School Assumptions'!$B$78 -> 0 | F30: =-E32/'School Assumptions'!$B$78 -> 0 | G30: =-F32/'School Assumptions'!$B$78 -> 0 | H30: =-G32/'School Assumptions'!$B$78 -> 0 | I30: =-H32/'School Assumptions'!$B$78 -> -76.153846 | J30: =-I32/'School Assumptions'!$B$78 -> -154.61538 | K30: =-J32/'School Assumptions'!$B$78 -> -306.92308 | L30: =-K32/'School Assumptions'!$B$78 -> -385.38462 | M30: =-L32/'School Assumptions'!$B$78 -> -537.69231
B31: New (at start of SY) | C31: =C32-(C28+C29) -> 0 | D31: =D32-(D28+D29+D30) -> 0 | E31: =E32-(E28+E29+E30) -> 0 | F31: =F32-(F28+F29+F30) -> 0 | G31: =G32-(G28+G29+G30) -> 0 | H31: =H32-(H28+H29+H30) -> 495 | I31: =I32-(I28+I29+I30) -> 623.15385 | J31: =J32-(J28+J29+J30) -> 1219.6154 | K31: =K32-(K28+K29+K30) -> 966.92308 | ... M31: =M32-(M28+M29+M30) -> 1309.6923
B32: Enrolled for SY | C32: =('School Assumptions'!$B$72*C20*C4)+('School Assumptions'!$B$73*C21*C4)+('School Assumptions'!$B$74*C22*C4)+('School Assumptions'!$B$75*C23*C4)+('School Assumptions'!$B$76*C24*C4) -> 0 | D32: =('School Assumptions'!$B$72*D20*D4)+('School Assumptions'!$B$73*D21*D4)+('School Assumptions'!$B$74*D22*D4)+('School Assumptions'!$B$75*D23*D4)+('School Assumptions'!$B$76*D24*D4) -> 0 | E32: =('School Assumptions'!$B$72*E20*E4)+('School Assumptions'!$B$73*E21*E4)+('School Assumptions'!$B$74*E22*E4)+('School Assumptions'!$B$75*E23*E4)+('School Assumptions'!$B$76*E24*E4) -> 0 | F32: =('School Assumptions'!$B$72*F20*F4)+('School Assumptions'!$B$73*F21*F4)+('School Assumptions'!$B$74*F22*F4)+('School Assumptions'!$B$75*F23*F4)+('School Assumptions'!$B$76*F24*F4) -> 0 | G32: =('School Assumptions'!$B$72*G20*G4)+('School Assumptions'!$B$73*G21*G4)+('School Assumptions'!$B$74*G22*G4)+('School Assumptions'!$B$75*G23*G4)+('School Assumptions'!$B$76*G24*G4) -> 0 | H32: =('School Assumptions'!$B$72*H20*H4)+('School Assumptions'!$B$73*H21*H4)+('School Assumptions'!$B$74*H22*H4)+('School Assumptions'!$B$75*H23*H4)+('School Assumptions'!$B$76*H24*H4) -> 495 | I32: =('School Assumptions'!$B$72*I20*I4)+('School Assumptions'!$B$73*I21*I4)+('School Assumptions'!$B$74*I22*I4)+('School Assumptions'!$B$75*I23*I4)+('School Assumptions'!$B$76*I24*I4) -> 1005 | J32: =('School Assumptions'!$B$72*J20*J4)+('School Assumptions'!$B$73*J21*J4)+('School Assumptions'!$B$74*J22*J4)+('School Assumptions'!$B$75*J23*J4)+('School Assumptions'!$B$76*J24*J4) -> 1995 | ... M32: =('School Assumptions'!$B$72*M20*M4)+('School Assumptions'!$B$73*M21*M4)+('School Assumptions'!$B$74*M22*M4)+('School Assumptions'!$B$75*M23*M4)+('School Assumptions'!$B$76*M24*M4) -> 4005
B34: Total Tuition Revenue | C34: =C32*C9 -> 0 | D34: =D32*D9 -> 0 | E34: =E32*E9 -> 0 | F34: =F32*F9 -> 0 | G34: =G32*G9 -> 0 | H34: =H32*H9 -> 24750000 | I34: =I32*I9 -> 50250000 | J34: =J32*J9 -> 99750000 | ... M34: =M32*M9 -> 200250000
B36: Expenses (per student)
B37: Headcount | C37: ='Headcount Assumptions'!$F$11 -> 5232.5 | D37: ='Headcount Assumptions'!$F$11 -> 5232.5 | E37: ='Headcount Assumptions'!$F$11 -> 5232.5 | F37: ='Headcount Assumptions'!$F$11 -> 5232.5 | G37: ='Headcount Assumptions'!$F$11 -> 5232.5 | H37: ='Headcount Assumptions'!$F$11 -> 5232.5 | I37: ='Headcount Assumptions'!$F$11 -> 5232.5 | J37: ='Headcount Assumptions'!$F$11 -> 5232.5 | ... M37: ='Headcount Assumptions'!$F$11 -> 5232.5
B38: Programs | C38: ='Headcount Assumptions'!$F$13+'Headcount Assumptions'!$F$14 -> 3000 | D38: ='Headcount Assumptions'!$F$13+'Headcount Assumptions'!$F$14 -> 3000 | E38: ='Headcount Assumptions'!$F$13+'Headcount Assumptions'!$F$14 -> 3000 | F38: ='Headcount Assumptions'!$F$13+'Headcount Assumptions'!$F$14 -> 3000 | G38: ='Headcount Assumptions'!$F$13+'Headcount Assumptions'!$F$14 -> 3000 | H38: ='Headcount Assumptions'!$F$13+'Headcount Assumptions'!$F$14 -> 3000 | I38: ='Headcount Assumptions'!$F$13+'Headcount Assumptions'!$F$14 -> 3000 | J38: ='Headcount Assumptions'!$F$13+'Headcount Assumptions'!$F$14 -> 3000 | ... M38: ='Headcount Assumptions'!$F$13+'Headcount Assumptions'!$F$14 -> 3000
B39: Misc. Expense | C39: 1500 | D39: 1500 | E39: 1500 | F39: 1500 | G39: 1500 | H39: 1500 | I39: 1500 | J39: 1500 | K39: 1500 | L39: 1500 | M39: 1500
B40: Timeback | C40: 5000 | D40: 5000 | E40: 5000 | F40: 5000 | G40: 5000 | H40: 5000 | I40: 5000 | J40: 5000 | K40: 5000 | L40: 5000 | M40: 5000
B41: Expenditures per Student | C41: =SUM(C37:C40) -> 14732.5 | D41: =SUM(D37:D40) -> 14732.5 | E41: =SUM(E37:E40) -> 14732.5 | F41: =SUM(F37:F40) -> 14732.5 | G41: =SUM(G37:G40) -> 14732.5 | H41: =SUM(H37:H40) -> 14732.5 | I41: =SUM(I37:I40) -> 14732.5 | J41: =SUM(J37:J40) -> 14732.5 | ... M41: =SUM(M37:M40) -> 14732.5
B42: Total Expenditures | C42: =C32*C41 -> 0 | D42: =D32*D41 -> 0 | E42: =E32*E41 -> 0 | F42: =F32*F41 -> 0 | G42: =G32*G41 -> 0 | H42: =H32*H41 -> 7292587.5 | I42: =I32*I41 -> 14806162 | J42: =J32*J41 -> 29391338 | ... M42: =M32*M41 -> 59003662
B44: Profit (ex-Facilities) | C44: =C34-C42 -> 0 | D44: =D34-D42 -> 0 | E44: =E34-E42 -> 0 | F44: =F34-F42 -> 0 | G44: =G34-G42 -> 0 | H44: =H34-H42 -> 17457412 | I44: =I34-I42 -> 35443838 | J44: =J34-J42 -> 70358662 | ... M44: =M34-M42 -> 1.4124634e+08
B46: Facilities Costs
B47: Purchases | C47: 0 | D47: =D20*((('School Assumptions'!$B$30*'School Assumptions'!$B$46)+('School Assumptions'!$B$40*(1-'School Assumptions'!$B$46)))) -> 0 | E47: =E20*((('School Assumptions'!$B$30*'School Assumptions'!$B$46)+('School Assumptions'!$B$40*(1-'School Assumptions'!$B$46)))) -> 0 | F47: =F20*'School Assumptions'!$B$66 -> 15000000 | G47: =G20*'School Assumptions'!$B$66 -> 0 | H47: =H20*'School Assumptions'!$B$66 -> 15000000 | I47: =I20*'School Assumptions'!$B$66 -> 0 | J47: =J20*'School Assumptions'!$B$66 -> 15000000 | K47: =K20*'School Assumptions'!$B$66 -> 0 | L47: =L20*'School Assumptions'!$B$66 -> 15000000 | M47: =M20*'School Assumptions'!$B$66 -> 0
...

